Workbook

Sheet Info
A1: Опис датасету
A2: Датасет містить інформацію про поїздки у службі таксі Uber, здійснені користувачем у 3х різних країнах.
A3: Період: | B3: 1.01.2016-31.12.2016
A5: Таблиця Uber Drives
A6: Колонка | B6: Значення
A7: TRAVEL_ID | B7: ідентифікатор замовлення таксі, унікальний для кожної поїздки, складається зі знаків "id_" та 3х значного числа.
A8: START_DATE | B8: дата та час початку поїздки.
A9: END_DATE | B9: дата та час закінчення поїздки.
A10: CATEGORY_ID | B10: числовий ідентифікатор категорії поїздки.
A11: START | B11: місцерозташування початкової точки маршруту.
A12: STOP | B12: місцерозташування кінцевої точки маршруту.
A13: MILES | B13: довжина маршруту, в милях.
A14: PURPOSE_ID | B14: числовий ідентифікатор цілі поїздки.
A17: Таблиця Category dict
A18: Колонка | B18: Значення
A19: CATEGORY | B19: категорія поїздки.
A20: CATEGORY_ID | B20: числовий ідентифікатор категорії поїздки.
A23: Таблиця Purpose dict
A24: Колонка | B24: Значення
A25: PURPOSE | B25: ціль поїздки.
A26: PURPOSE_ID | B26: числовий ідентифікатор цілі поїздки.

Sheet Purpose dict
A1: PURPOSE_ID | B1: PURPOSE
A2: 1 | B2: Meal/Entertain
A3: 123 | B3: NOT DEFINED
A4: 2 | B4: Errand/Supplies
A5: 3 | B5: Meeting
A6: 4 | B6: Customer Visit
A7: 5 | B7: Temporary Site
A8: 6 | B8: Between Offices
A9: 7 | B9: Charity ($)
A10: 8 | B10: Commute
A11: 9 | B11: Moving
A12: 10 | B12: Airport/Travel

Sheet Category dict
A1: CATEGORY | B1: CATEGORY_ID
A2: Business | B2: 423
A3: Personal | B3: 527
A4: Other | B4: 111

Sheet Uber Drives
A1: TRAVEL_ID | B1: START_DATE | C1: END_DATE | D1: CATEGORY_ID | E1: START_LOCATION | F1: STOP_LOCATION | G1: MILES | H1: PURPOSE_ID | I1: START_TIME | J1: END_TIME | K1: DURATION | L1: START_TIME_DAYPART | M1: CATEGORY | N1: PURPOSE
A2: id_237 | B2: 42370.883 | C2: 42370.887 | D2: 423 | E2: Fort Pierce | F2: Fort Pierce | G2: 5.1 | H2: 1 | I2: 0.88263889 | J2: 0.88680556 | K2: =J2-I2 -> 0.0041666667 | L2: =ifs(I2<=TIME(6,0,0),"Night",I2<=TIME(12,0,0),"Morning",I2<=TIME(18,0,0),"Day",I2<=TIME(23,59,59),"Evening") -> Evening | M2: {=XLOOKUP(D2,'Category dict'!$B$1:$B$4,'Category dict'!$A$1:$A$4,0,0,1)} -> Business | N2: =VLOOKUP(H2,'Purpose dict'!$A$1:$B$12,2,0) -> Meal/Entertain
A3: id_238 | B3: 42371.059 | C3: 42371.067 | D3: 423 | E3: Fort Pierce | F3: Fort Pierce | G3: 5 | H3: 123 | I3: 0.059027778 | J3: 0.067361111 | K3: =J3-I3 -> 0.0083333333 | L3: =ifs(I3<=TIME(6,0,0),"Night",I3<=TIME(12,0,0),"Morning",I3<=TIME(18,0,0),"Day",I3<=TIME(23,59,59),"Evening") -> Night | M3: {=XLOOKUP(D3,'Category dict'!$B$1:$B$4,'Category dict'!$A$1:$A$4,0,0,1)} -> Business | N3: =VLOOKUP(H3,'Purpose dict'!$A$1:$B$12,2,0) -> NOT DEFINED
A4: id_239 | B4: 42371.851 | C4: 42371.86 | D4: 423 | E4: Fort Pierce | F4: Fort Pierce | G4: 4.8 | H4: 2 | I4: 0.85069444 | J4: 0.85972222 | K4: =J4-I4 -> 0.0090277778 | L4: =ifs(I4<=TIME(6,0,0),"Night",I4<=TIME(12,0,0),"Morning",I4<=TIME(18,0,0),"Day",I4<=TIME(23,59,59),"Evening") -> Evening | M4: {=XLOOKUP(D4,'Category dict'!$B$1:$B$4,'Category dict'!$A$1:$A$4,0,0,1)} -> Business | N4: =VLOOKUP(H4,'Purpose dict'!$A$1:$B$12,2,0) -> Errand/Supplies
A5: id_240 | B5: 42374.73 | C5: 42374.74 | D5: 423 | E5: Fort Pierce | F5: Fort Pierce | G5: 4.7 | H5: 3 | I5: 0.72986111 | J5: 0.73958333 | K5: =J5-I5 -> 0.0097222222 | L5: =ifs(I5<=TIME(6,0,0),"Night",I5<=TIME(12,0,0),"Morning",I5<=TIME(18,0,0),"Day",I5<=TIME(23,59,59),"Evening") -> Day | M5: {=XLOOKUP(D5,'Category dict'!$B$1:$B$4,'Category dict'!$A$1:$A$4,0,0,1)} -> Business | N5: =VLOOKUP(H5,'Purpose dict'!$A$1:$B$12,2,0) -> Meeting
A6: id_241 | B6: 42375.613 | C6: 42375.659 | D6: 423 | E6: Fort Pierce | F6: West Palm Beach | G6: 63.7 | H6: 4 | I6: 0.6125 | J6: 0.65902778 | K6: =J6-I6 -> 0.046527778 | L6: =ifs(I6<=TIME(6,0,0),"Night",I6<=TIME(12,0,0),"Morning",I6<=TIME(18,0,0),"Day",I6<=TIME(23,59,59),"Evening") -> Day | M6: {=XLOOKUP(D6,'Category dict'!$B$1:$B$4,'Category dict'!$A$1:$A$4,0,0,1)} -> Business | N6: =VLOOKUP(H6,'Purpose dict'!$A$1:$B$12,2,0) -> Customer Visit
A7: id_242 | B7: 42375.719 | C7: 42375.722 | D7: 423 | E7: West Palm Beach | F7: West Palm Beach | G7: 4.3 | H7: 1 | I7: 0.71875 | J7: 0.72152778 | K7: =J7-I7 -> 0.0027777778 | L7: =ifs(I7<=TIME(6,0,0),"Night",I7<=TIME(12,0,0),"Morning",I7<=TIME(18,0,0),"Day",I7<=TIME(23,59,59),"Evening") -> Day | M7: {=XLOOKUP(D7,'Category dict'!$B$1:$B$4,'Category dict'!$A$1:$A$4,0,0,1)} -> Business | N7: =VLOOKUP(H7,'Purpose dict'!$A$1:$B$12,2,0) -> Meal/Entertain
A8: id_243 | B8: 42375.729 | C8: 42375.733 | D8: 423 | E8: West Palm Beach | F8: Palm Beach | G8: 7.1 | H8: 3 | I8: 0.72916667 | J8: 0.73263889 | K8: =J8-I8 -> 0.0034722222 | L8: =ifs(I8<=TIME(6,0,0),"Night",I8<=TIME(12,0,0),"Morning",I8<=TIME(18,0,0),"Day",I8<=TIME(23,59,59),"Evening") -> Day | M8: {=XLOOKUP(D8,'Category dict'!$B$1:$B$4,'Category dict'!$A$1:$A$4,0,0,1)} -> Business | N8: =VLOOKUP(H8,'Purpose dict'!$A$1:$B$12,2,0) -> Meeting
A9: id_244 | B9: 42376.56 | C9: 42376.565 | D9: 423 | E9: Cary | F9: Cary | G9: 0.8 | H9: 3 | I9: 0.56041667 | J9: 0.56458333 | K9: =J9-I9 -> 0.0041666667 | L9: =ifs(I9<=TIME(6,0,0),"Night",I9<=TIME(12,0,0),"Morning",I9<=TIME(18,0,0),"Day",I9<=TIME(23,59,59),"Evening") -> Day | M9: {=XLOOKUP(D9,'Category dict'!$B$1:$B$4,'Category dict'!$A$1:$A$4,0,0,1)} -> Business | N9: =VLOOKUP(H9,'Purpose dict'!$A$1:$B$12,2,0) -> Meeting
A10: id_245 | B10: 42379.337 | C10: 42379.351 | D10: 423 | E10: Cary | F10: Morrisville | G10: 8.3 | H10: 3 | I10: 0.33680556 | J10: 0.35069444 | K10: =J10-I10 -> 0.013888889 | L10: =ifs(I10<=TIME(6,0,0),"Night",I10<=TIME(12,0,0),"Morning",I10<=TIME(18,0,0),"Day",I10<=TIME(23,59,59),"Evening") -> Morning | M10: {=XLOOKUP(D10,'Category dict'!$B$1:$B$4,'Category dict'!$A$1:$A$4,0,0,1)} -> Business | N10: =VLOOKUP(H10,'Purpose dict'!$A$1:$B$12,2,0) -> Meeting
A11: id_246 | B11: 42379.512 | C11: 42379.531 | D11: 423 | E11: Jamaica | F11: New York | G11: 16.5 | H11: 4 | I11: 0.51180556 | J11: 0.53055556 | K11: =J11-I11 -> 0.01875 | L11: =ifs(I11<=TIME(6,0,0),"Night",I11<=TIME(12,0,0),"Morning",I11<=TIME(18,0,0),"Day",I11<=TIME(23,59,59),"Evening") -> Day | M11: {=XLOOKUP(D11,'Category dict'!$B$1:$B$4,'Category dict'!$A$1:$A$4,0,0,1)} -> Business | N11: =VLOOKUP(H11,'Purpose dict'!$A$1:$B$12,2,0) -> Customer Visit
A12: id_247 | B12: 42379.631 | C12: 42379.66 | D12: 423 | E12: New York | F12: Queens | G12: 10.8 | H12: 3 | I12: 0.63055556 | J12: 0.66041667 | K12: =J12-I12 -> 0.029861111 | L12: =ifs(I12<=TIME(6,0,0),"Night",I12<=TIME(12,0,0),"Morning",I12<=TIME(18,0,0),"Day",I12<=TIME(23,59,59),"Evening") -> Day | M12: {=XLOOKUP(D12,'Category dict'!$B$1:$B$4,'Category dict'!$A$1:$A$4,0,0,1)} -> Business | N12: =VLOOKUP(H12,'Purpose dict'!$A$1:$B$12,2,0) -> Meeting
A13: id_248 | B13: 42379.762 | C13: 42379.787 | D13: 423 | E13: Elmhurst | F13: New York | G13: 7.5 | H13: 3 | I13: 0.7625 | J13: 0.78680556 | K13: =J13-I13 -> 0.024305556 | L13: =ifs(I13<=TIME(6,0,0),"Night",I13<=TIME(12,0,0),"Morning",I13<=TIME(18,0,0),"Day",I13<=TIME(23,59,59),"Evening") -> Evening | M13: {=XLOOKUP(D13,'Category dict'!$B$1:$B$4,'Category dict'!$A$1:$A$4,0,0,1)} -> Business | N13: =VLOOKUP(H13,'Purpose dict'!$A$1:$B$12,2,0) -> Meeting
... A103: id_338 | B103: 42413.598 | C103: 42413.612 | D103: 423 | E103: Cary | F103: Morrisville | G103: 8.9 | H103: 3 | I103: 0.59791667 | J103: 0.61180556 | K103: =J103-I103 -> 0.013888889 | L103: =ifs(I103<=TIME(6,0,0),"Night",I103<=TIME(12,0,0),"Morning",I103<=TIME(18,0,0),"Day",I103<=TIME(23,59,59),"Evening") -> Day | M103: {=XLOOKUP(D103,'Category dict'!$B$1:$B$4,'Category dict'!$A$1:$A$4,0,0,1)} -> Business | N103: =VLOOKUP(H103,'Purpose dict'!$A$1:$B$12,2,0) -> Meeting
A104: id_339 | B104: 42413.99 | C104: 42414.001 | D104: 527 | E104: East Elmhurst | F104: Jackson Heights | G104: 2.7 | H104: 123 | I104: 0.98958333 | J104: 0.00069444444 | K104: =C104-B104 -> 0.011111111 | L104: =ifs(I104<=TIME(6,0,0),"Night",I104<=TIME(12,0,0),"Morning",I104<=TIME(18,0,0),"Day",I104<=TIME(23,59,59),"Evening") -> Evening | M104: {=XLOOKUP(D104,'Category dict'!$B$1:$B$4,'Category dict'!$A$1:$A$4,0,0,1)} -> Personal | N104: =VLOOKUP(H104,'Purpose dict'!$A$1:$B$12,2,0) -> NOT DEFINED
A105: id_340 | B105: 42414.035 | C105: 42414.042 | D105: 527 | E105: Jackson Heights | F105: East Elmhurst | G105: 1.8 | H105: 123 | I105: 0.034722222 | J105: 0.041666667 | K105: =J105-I105 -> 0.0069444444 | L105: =ifs(I105<=TIME(6,0,0),"Night",I105<=TIME(12,0,0),"Morning",I105<=TIME(18,0,0),"Day",I105<=TIME(23,59,59),"Evening") -> Night | M105: {=XLOOKUP(D105,'Category dict'!$B$1:$B$4,'Category dict'!$A$1:$A$4,0,0,1)} -> Personal | N105: =VLOOKUP(H105,'Purpose dict'!$A$1:$B$12,2,0) -> NOT DEFINED
A106: id_341 | B106: 42414.588 | C106: 42414.611 | D106: 423 | E106: East Elmhurst | F106: New York | G106: 8.1 | H106: 3 | I106: 0.58819444 | J106: 0.61111111 | K106: =J106-I106 -> 0.022916667 | L106: =ifs(I106<=TIME(6,0,0),"Night",I106<=TIME(12,0,0),"Morning",I106<=TIME(18,0,0),"Day",I106<=TIME(23,59,59),"Evening") -> Day | M106: {=XLOOKUP(D106,'Category dict'!$B$1:$B$4,'Category dict'!$A$1:$A$4,0,0,1)} -> Business | N106: =VLOOKUP(H106,'Purpose dict'!$A$1:$B$12,2,0) -> Meeting
A107: id_342 | B107: 42414.615 | C107: 42414.627 | D107: 423 | E107: Midtown | F107: Midtown West | G107: 2 | H107: 3 | I107: 0.61527778 | J107: 0.62708333 | K107: =J107-I107 -> 0.011805556 | L107: =ifs(I107<=TIME(6,0,0),"Night",I107<=TIME(12,0,0),"Morning",I107<=TIME(18,0,0),"Day",I107<=TIME(23,59,59),"Evening") -> Day | M107: {=XLOOKUP(D107,'Category dict'!$B$1:$B$4,'Category dict'!$A$1:$A$4,0,0,1)} -> Business | N107: =VLOOKUP(H107,'Purpose dict'!$A$1:$B$12,2,0) -> Meeting
A108: id_343 | B108: 42414.691 | C108: 42414.71 | D108: 423 | E108: New York | F108: Long Island City | G108: 13 | H108: 3 | I108: 0.69097222 | J108: 0.70972222 | K108: =J108-I108 -> 0.01875 | L108: =ifs(I108<=TIME(6,0,0),"Night",I108<=TIME(12,0,0),"Morning",I108<=TIME(18,0,0),"Day",I108<=TIME(23,59,59),"Evening") -> Day | M108: {=XLOOKUP(D108,'Category dict'!$B$1:$B$4,'Category dict'!$A$1:$A$4,0,0,1)} -> Business | N108: =VLOOKUP(H108,'Purpose dict'!$A$1:$B$12,2,0) -> Meeting
A109: id_344 | B109: 42414.713 | C109: 42414.728 | D109: 423 | E109: Long Island City | F109: Jamaica | G109: 13.9 | H109: 3 | I109: 0.7125 | J109: 0.72847222 | K109: =J109-I109 -> 0.015972222 | L109: =ifs(I109<=TIME(6,0,0),"Night",I109<=TIME(12,0,0),"Morning",I109<=TIME(18,0,0),"Day",I109<=TIME(23,59,59),"Evening") -> Day | M109: {=XLOOKUP(D109,'Category dict'!$B$1:$B$4,'Category dict'!$A$1:$A$4,0,0,1)} -> Business | N109: =VLOOKUP(H109,'Purpose dict'!$A$1:$B$12,2,0) -> Meeting
A110: id_345 | B110: 42416.14 | C110: 42416.176 | D110: 423 | E110: Katunayaka | F110: Unknown Location | G110: 43.7 | H110: 4 | I110: 0.13958333 | J110: 0.17569444 | K110: =J110-I110 -> 0.036111111 | L110: =ifs(I110<=TIME(6,0,0),"Night",I110<=TIME(12,0,0),"Morning",I110<=TIME(18,0,0),"Day",I110<=TIME(23,59,59),"Evening") -> Night | M110: {=XLOOKUP(D110,'Category dict'!$B$1:$B$4,'Category dict'!$A$1:$A$4,0,0,1)} -> Business | N110: =VLOOKUP(H110,'Purpose dict'!$A$1:$B$12,2,0) -> Customer Visit
A111: id_346 | B111: 42416.353 | C111: 42416.399 | D111: 423 | E111: Unknown Location | F111: Colombo | G111: 14.1 | H111: 123 | I111: 0.35347222 | J111: 0.39861111 | K111: =J111-I111 -> 0.045138889 | L111: =ifs(I111<=TIME(6,0,0),"Night",I111<=TIME(12,0,0),"Morning",I111<=TIME(18,0,0),"Day",I111<=TIME(23,59,59),"Evening") -> Morning | M111: {=XLOOKUP(D111,'Category dict'!$B$1:$B$4,'Category dict'!$A$1:$A$4,0,0,1)} -> Business | N111: =VLOOKUP(H111,'Purpose dict'!$A$1:$B$12,2,0) -> NOT DEFINED
A112: id_347 | B112: 42416.438 | C112: 42416.445 | D112: 423 | E112: Colombo | F112: Colombo | G112: 2.6 | H112: 123 | I112: 0.43819444 | J112: 0.44513889 | K112: =J112-I112 -> 0.0069444444 | L112: =ifs(I112<=TIME(6,0,0),"Night",I112<=TIME(12,0,0),"Morning",I112<=TIME(18,0,0),"Day",I112<=TIME(23,59,59),"Evening") -> Morning | M112: {=XLOOKUP(D112,'Category dict'!$B$1:$B$4,'Category dict'!$A$1:$A$4,0,0,1)} -> Business | N112: =VLOOKUP(H112,'Purpose dict'!$A$1:$B$12,2,0) -> NOT DEFINED
A113: id_348 | B113: 42416.481 | C113: 42416.501 | D113: 423 | E113: Colombo | F113: Colombo | G113: 4.5 | H113: 123 | I113: 0.48055556 | J113: 0.50138889 | K113: =J113-I113 -> 0.020833333 | L113: =ifs(I113<=TIME(6,0,0),"Night",I113<=TIME(12,0,0),"Morning",I113<=TIME(18,0,0),"Day",I113<=TIME(23,59,59),"Evening") -> Morning | M113: {=XLOOKUP(D113,'Category dict'!$B$1:$B$4,'Category dict'!$A$1:$A$4,0,0,1)} -> Business | N113: =VLOOKUP(H113,'Purpose dict'!$A$1:$B$12,2,0) -> NOT DEFINED
A114: id_349 | B114: 42416.527 | C114: 42416.529 | D114: 423 | E114: Colombo | F114: Colombo | G114: 1.7 | H114: 123 | I114: 0.52708333 | J114: 0.52916667 | K114: =J114-I114 -> 0.0020833333 | L114: =ifs(I114<=TIME(6,0,0),"Night",I114<=TIME(12,0,0),"Morning",I114<=TIME(18,0,0),"Day",I114<=TIME(23,59,59),"Evening") -> Day | M114: {=XLOOKUP(D114,'Category dict'!$B$1:$B$4,'Category dict'!$A$1:$A$4,0,0,1)} -> Business | N114: =VLOOKUP(H114,'Purpose dict'!$A$1:$B$12,2,0) -> NOT DEFINED
A115: id_350 | B115: 42416.572 | C115: 42416.58 | D115: 423 | E115: Colombo | F115: Colombo | G115: 1.8 | H115: 5 | I115: 0.57152778 | J115: 0.57986111 | K115: =J115-I115 -> 0.0083333333 | L115: =ifs(I115<=TIME(6,0,0),"Night",I115<=TIME(12,0,0),"Morning",I115<=TIME(18,0,0),"Day",I115<=TIME(23,59,59),"Evening") -> Day | M115: {=XLOOKUP(D115,'Category dict'!$B$1:$B$4,'Category dict'!$A$1:$A$4,0,0,1)} -> Business | N115: =VLOOKUP(H115,'Purpose dict'!$A$1:$B$12,2,0) -> Temporary Site
A116: id_351 | B116: 42416.69 | C116: 42416.715 | D116: 423 | E116: Colombo | F116: Colombo | G116: 6 | H116: 123 | I116: 0.69027778 | J116: 0.71527778 | K116: =J116-I116 -> 0.025 | L116: =ifs(I116<=TIME(6,0,0),"Night",I116<=TIME(12,0,0),"Morning",I116<=TIME(18,0,0),"Day",I116<=TIME(23,59,59),"Evening") -> Day | M116: {=XLOOKUP(D116,'Category dict'!$B$1:$B$4,'Category dict'!$A$1:$A$4,0,0,1)} -> Business | N116: =VLOOKUP(H116,'Purpose dict'!$A$1:$B$12,2,0) -> NOT DEFINED
... A271: id_506 | B271: 42454.703 | C271: 42454.932 | D271: 423 | E271: Latta | F271: Jacksonville | G271: 310.3 | H271: 4 | I271: 0.70277778 | J271: 0.93194444 | K271: =J271-I271 -> 0.22916667 | L271: =ifs(I271<=TIME(6,0,0),"Night",I271<=TIME(12,0,0),"Morning",I271<=TIME(18,0,0),"Day",I271<=TIME(23,59,59),"Evening") -> Day | M271: {=XLOOKUP(D271,'Category dict'!$B$1:$B$4,'Category dict'!$A$1:$A$4,0,0,1)} -> Business | N271: =VLOOKUP(H271,'Purpose dict'!$A$1:$B$12,2,0) -> Customer Visit
A272: id_507 | B272: 42454.954 | C272: 42455.069 | D272: 423 | E272: Jacksonville | F272: Kissimmee | G272: 201 | H272: 3 | I272: 0.95416667 | J272: 0.06875 | K272: =C272-B272 -> 0.11458333 | L272: =ifs(I272<=TIME(6,0,0),"Night",I272<=TIME(12,0,0),"Morning",I272<=TIME(18,0,0),"Day",I272<=TIME(23,59,59),"Evening") -> Evening | M272: {=XLOOKUP(D272,'Category dict'!$B$1:$B$4,'Category dict'!$A$1:$A$4,0,0,1)} -> Business | N272: =VLOOKUP(H272,'Purpose dict'!$A$1:$B$12,2,0) -> Meeting
A273: id_508 | B273: 42455.587 | C273: 42455.603 | D273: 527 | E273: Couples Glen | F273: Isles of Buena Vista | G273: 6.7 | H273: 123 | I273: 0.58680556 | J273: 0.60347222 | K273: =J273-I273 -> 0.016666667 | L273: =ifs(I273<=TIME(6,0,0),"Night",I273<=TIME(12,0,0),"Morning",I273<=TIME(18,0,0),"Day",I273<=TIME(23,59,59),"Evening") -> Day | M273: {=XLOOKUP(D273,'Category dict'!$B$1:$B$4,'Category dict'!$A$1:$A$4,0,0,1)} -> Personal | N273: =VLOOKUP(H273,'Purpose dict'!$A$1:$B$12,2,0) -> NOT DEFINED
A274: id_509 | B274: 42455.638 | C274: 42455.659 | D274: 527 | E274: Kissimmee | F274: Orlando | G274: 8.8 | H274: 123 | I274: 0.63819444 | J274: 0.65902778 | K274: =J274-I274 -> 0.020833333 | L274: =ifs(I274<=TIME(6,0,0),"Night",I274<=TIME(12,0,0),"Morning",I274<=TIME(18,0,0),"Day",I274<=TIME(23,59,59),"Evening") -> Day | M274: {=XLOOKUP(D274,'Category dict'!$B$1:$B$4,'Category dict'!$A$1:$A$4,0,0,1)} -> Personal | N274: =VLOOKUP(H274,'Purpose dict'!$A$1:$B$12,2,0) -> NOT DEFINED
A275: id_510 | B275: 42455.685 | C275: 42455.688 | D275: 527 | E275: Lake Reams | F275: Lake Reams | G275: 1.2 | H275: 123 | I275: 0.68472222 | J275: 0.6875 | K275: =J275-I275 -> 0.0027777778 | L275: =ifs(I275<=TIME(6,0,0),"Night",I275<=TIME(12,0,0),"Morning",I275<=TIME(18,0,0),"Day",I275<=TIME(23,59,59),"Evening") -> Day | M275: {=XLOOKUP(D275,'Category dict'!$B$1:$B$4,'Category dict'!$A$1:$A$4,0,0,1)} -> Personal | N275: =VLOOKUP(H275,'Purpose dict'!$A$1:$B$12,2,0) -> NOT DEFINED
A276: id_511 | B276: 42456.022 | C276: 42456.028 | D276: 423 | E276: Lake Reams | F276: Lake Reams | G276: 2.1 | H276: 2 | I276: 0.021527778 | J276: 0.027777778 | K276: =J276-I276 -> 0.00625 | L276: =ifs(I276<=TIME(6,0,0),"Night",I276<=TIME(12,0,0),"Morning",I276<=TIME(18,0,0),"Day",I276<=TIME(23,59,59),"Evening") -> Night | M276: {=XLOOKUP(D276,'Category dict'!$B$1:$B$4,'Category dict'!$A$1:$A$4,0,0,1)} -> Business | N276: =VLOOKUP(H276,'Purpose dict'!$A$1:$B$12,2,0) -> Errand/Supplies
A277: id_512 | B277: 42456.049 | C277: 42456.058 | D277: 423 | E277: Orlando | F277: Kissimmee | G277: 6.6 | H277: 1 | I277: 0.049305556 | J277: 0.057638889 | K277: =J277-I277 -> 0.0083333333 | L277: =ifs(I277<=TIME(6,0,0),"Night",I277<=TIME(12,0,0),"Morning",I277<=TIME(18,0,0),"Day",I277<=TIME(23,59,59),"Evening") -> Night | M277: {=XLOOKUP(D277,'Category dict'!$B$1:$B$4,'Category dict'!$A$1:$A$4,0,0,1)} -> Business | N277: =VLOOKUP(H277,'Purpose dict'!$A$1:$B$12,2,0) -> Meal/Entertain
A278: id_513 | B278: 42456.647 | C278: 42456.664 | D278: 423 | E278: Kissimmee | F278: Orlando | G278: 6.1 | H278: 4 | I278: 0.64652778 | J278: 0.66388889 | K278: =J278-I278 -> 0.017361111 | L278: =ifs(I278<=TIME(6,0,0),"Night",I278<=TIME(12,0,0),"Morning",I278<=TIME(18,0,0),"Day",I278<=TIME(23,59,59),"Evening") -> Day | M278: {=XLOOKUP(D278,'Category dict'!$B$1:$B$4,'Category dict'!$A$1:$A$4,0,0,1)} -> Business | N278: =VLOOKUP(H278,'Purpose dict'!$A$1:$B$12,2,0) -> Customer Visit
A279: id_514 | B279: 42456.893 | C279: 42456.903 | D279: 527 | E279: Orlando | F279: Orlando | G279: 6.9 | H279: 123 | I279: 0.89305556 | J279: 0.90347222 | K279: =J279-I279 -> 0.010416667 | L279: =ifs(I279<=TIME(6,0,0),"Night",I279<=TIME(12,0,0),"Morning",I279<=TIME(18,0,0),"Day",I279<=TIME(23,59,59),"Evening") -> Evening | M279: {=XLOOKUP(D279,'Category dict'!$B$1:$B$4,'Category dict'!$A$1:$A$4,0,0,1)} -> Personal | N279: =VLOOKUP(H279,'Purpose dict'!$A$1:$B$12,2,0) -> NOT DEFINED
A280: id_515 | B280: 42456.961 | C280: 42456.971 | D280: 527 | E280: Orlando | F280: Kissimmee | G280: 7.3 | H280: 123 | I280: 0.96111111 | J280: 0.97083333 | K280: =J280-I280 -> 0.0097222222 | L280: =ifs(I280<=TIME(6,0,0),"Night",I280<=TIME(12,0,0),"Morning",I280<=TIME(18,0,0),"Day",I280<=TIME(23,59,59),"Evening") -> Evening | M280: {=XLOOKUP(D280,'Category dict'!$B$1:$B$4,'Category dict'!$A$1:$A$4,0,0,1)} -> Personal | N280: =VLOOKUP(H280,'Purpose dict'!$A$1:$B$12,2,0) -> NOT DEFINED
A281: id_516 | B281: 42457.52 | C281: 42457.529 | D281: 527 | E281: Kissimmee | F281: Orlando | G281: 3.6 | H281: 123 | I281: 0.52013889 | J281: 0.52916667 | K281: =J281-I281 -> 0.0090277778 | L281: =ifs(I281<=TIME(6,0,0),"Night",I281<=TIME(12,0,0),"Morning",I281<=TIME(18,0,0),"Day",I281<=TIME(23,59,59),"Evening") -> Day | M281: {=XLOOKUP(D281,'Category dict'!$B$1:$B$4,'Category dict'!$A$1:$A$4,0,0,1)} -> Personal | N281: =VLOOKUP(H281,'Purpose dict'!$A$1:$B$12,2,0) -> NOT DEFINED
A282: id_517 | B282: 42457.812 | C282: 42457.849 | D282: 527 | E282: Couples Glen | F282: Vista East | G282: 27.2 | H282: 123 | I282: 0.8125 | J282: 0.84930556 | K282: =J282-I282 -> 0.036805556 | L282: =ifs(I282<=TIME(6,0,0),"Night",I282<=TIME(12,0,0),"Morning",I282<=TIME(18,0,0),"Day",I282<=TIME(23,59,59),"Evening") -> Evening | M282: {=XLOOKUP(D282,'Category dict'!$B$1:$B$4,'Category dict'!$A$1:$A$4,0,0,1)} -> Personal | N282: =VLOOKUP(H282,'Purpose dict'!$A$1:$B$12,2,0) -> NOT DEFINED
A283: id_518 | B283: 42457.955 | C283: 42457.976 | D283: 527 | E283: Orlando | F283: Kissimmee | G283: 25.7 | H283: 123 | I283: 0.95486111 | J283: 0.97638889 | K283: =J283-I283 -> 0.021527778 | L283: =ifs(I283<=TIME(6,0,0),"Night",I283<=TIME(12,0,0),"Morning",I283<=TIME(18,0,0),"Day",I283<=TIME(23,59,59),"Evening") -> Evening | M283: {=XLOOKUP(D283,'Category dict'!$B$1:$B$4,'Category dict'!$A$1:$A$4,0,0,1)} -> Personal | N283: =VLOOKUP(H283,'Purpose dict'!$A$1:$B$12,2,0) -> NOT DEFINED
...

Sheet Result
A2: 0. Пошук аномальних значень
A3: Назва колонки | B3: Кількість записів | C3: Кількість порожніх записів | D3: Кількість записів із NA значенням | E3: Кількість відʼємних записів
A4: TRAVEL_ID | B4: =COUNTA('Uber Drives'!A2:A1152) -> 1151 | C4: =COUNTBLANK('Uber Drives'!A2:A1152) -> 0 | D4: =COUNTIF('Uber Drives'!A2:A1152, "#N/A") -> 0 | E4: =COUNTIF('Uber Drives'!A2:A1152, "<0") -> 0
A5: START_DATE | B5: =COUNTA('Uber Drives'!B2:B1152) -> 1151 | C5: =COUNTBLANK('Uber Drives'!B2:B1152) -> 0 | D5: =COUNTIF('Uber Drives'!B2:B1152, "#N/A") -> 0 | E5: =COUNTIF('Uber Drives'!B2:B1152, "<0") -> 0
A6: END_DATE | B6: =COUNTA('Uber Drives'!C2:C1152) -> 1151 | C6: =COUNTBLANK('Uber Drives'!C2:C1152) -> 0 | D6: =COUNTIF('Uber Drives'!C2:C1152, "#N/A") -> 0 | E6: =COUNTIF('Uber Drives'!C2:C1152, "<0") -> 0
A7: CATEGORY_ID | B7: =COUNTA('Uber Drives'!D2:D1152) -> 1151 | C7: =COUNTBLANK('Uber Drives'!D2:D1152) -> 0 | D7: =COUNTIF('Uber Drives'!D2:D1152, "#N/A") -> 0 | E7: =COUNTIF('Uber Drives'!D2:D1152, "<0") -> 0
A8: START_LOCATION | B8: =COUNTA('Uber Drives'!E2:E1152) -> 1151 | C8: =COUNTBLANK('Uber Drives'!E2:E1152) -> 0 | D8: =COUNTIF('Uber Drives'!E2:E1152, "#N/A") -> 0 | E8: =COUNTIF('Uber Drives'!E2:E1152, "<0") -> 0
A9: STOP_LOCATION | B9: =COUNTA('Uber Drives'!F2:F1152) -> 1151 | C9: =COUNTBLANK('Uber Drives'!F2:F1152) -> 0 | D9: =COUNTIF('Uber Drives'!F2:F1152, "#N/A") -> 0 | E9: =COUNTIF('Uber Drives'!F2:F1152, "<0") -> 0
A10: MILES | B10: =COUNTA('Uber Drives'!G2:G1152) -> 1151 | C10: =COUNTBLANK('Uber Drives'!G2:G1152) -> 0 | D10: =COUNTIF('Uber Drives'!G2:G1152, "#N/A") -> 0 | E10: =COUNTIF('Uber Drives'!G2:G1152, "<0") -> 0
A11: PURPOSE_ID | B11: =COUNTA('Uber Drives'!H2:H1152) -> 1151 | C11: =COUNTBLANK('Uber Drives'!H2:H1152) -> 0 | D11: =COUNTIF('Uber Drives'!H2:H1152, "#N/A") -> 0 | E11: =COUNTIF('Uber Drives'!H2:H1152, "<0") -> 0
A12: START_TIME | B12: =COUNTA('Uber Drives'!I2:I1152) -> 1151 | C12: =COUNTBLANK('Uber Drives'!I2:I1152) -> 0 | D12: =COUNTIF('Uber Drives'!I2:I1152, "#N/A") -> 0 | E12: =COUNTIF('Uber Drives'!I2:I1152, "<0") -> 0
A13: END_TIME | B13: =COUNTA('Uber Drives'!J2:J1152) -> 1151 | C13: =COUNTBLANK('Uber Drives'!J2:J1152) -> 0 | D13: =COUNTIF('Uber Drives'!J2:J1152, "#N/A") -> 0 | E13: =COUNTIF('Uber Drives'!J2:J1152, "<0") -> 0
A14: DURATION | B14: =COUNTA('Uber Drives'!K2:K1152) -> 1151 | C14: =COUNTBLANK('Uber Drives'!K2:K1152) -> 0 | D14: =COUNTIF('Uber Drives'!K2:K1152, "#N/A") -> 0 | E14: =COUNTIF('Uber Drives'!K2:K1152, "<0") -> 0
A15: START_TIME_DAYPART | B15: =COUNTA('Uber Drives'!L2:L1152) -> 1151 | C15: =COUNTBLANK('Uber Drives'!L2:L1152) -> 0 | D15: =COUNTIF('Uber Drives'!L2:L1152, "#N/A") -> 0 | E15: =COUNTIF('Uber Drives'!L2:L1152, "<0") -> 0
A16: CATEGORY | B16: =COUNTA('Uber Drives'!M2:M1152) -> 1151 | C16: =COUNTBLANK('Uber Drives'!M2:M1152) -> 0 | D16: =COUNTIF('Uber Drives'!M2:M1152, "#N/A") -> 0 | E16: =COUNTIF('Uber Drives'!M2:M1152, "<0") -> 0
A17: PURPOSE | B17: =COUNTA('Uber Drives'!N2:N1152) -> 1151 | C17: =COUNTBLANK('Uber Drives'!N2:N1152) -> 0 | D17: =COUNTIF('Uber Drives'!N2:N1152, "#N/A") -> 0 | E17: =COUNTIF('Uber Drives'!N2:N1152, "<0") -> 0
A19: 1. Аналіз поїздок за категоріями та ціллю - кількість поїздок, середня тривалість поїздок, середня довжина поїздок (милі)
A20: a. Підрахунок за допомогою формул | H20: AVERAGEIF('Uber Drives'!$M$2:$M$1156,$A$23,'Uber Drives'!$K$2:$K$1156)
A21: Категорія (текстова назва) | B21: Кількість поїздок | C21: Середня тривалість поїздок | D21: Середня довжина поїздок (милі) | F21: Ціль поїздки (текстова назва) | G21: Кількість поїздок | H21: Середня тривалість поїздок | I21: Середня довжина поїздок (милі) | K21: Категорія (текстова назва) | L21: Ціль поїздки (текстова назва) | M21: Кількість поїздок | N21: Середня тривалість поїздок | O21: Середня довжина поїздок (милі)
A22: {=UNIQUE('Uber Drives'!M2:M1152)} -> Business | B22: =COUNTIF('Uber Drives'!$M$2:$M$1152,A22) -> 1074 | C22: =AVERAGEIF('Uber Drives'!$M$2:$M$1152,$A$22,'Uber Drives'!$K$2:$K$1152) -> 0.016340136 | D22: =ROUND(AVERAGEIF('Uber Drives'!$M$2:$M$1152,$A$22,'Uber Drives'!$G$2:$G$1152),2) -> 10.63 | F22: {=UNIQUE('Uber Drives'!N2:N1152)} -> Meal/Entertain | G22: =COUNTIF('Uber Drives'!$N$2:$N$1152,F22) -> 160 | H22: =AVERAGEIF('Uber Drives'!$N$2:$N$1152,F22,'Uber Drives'!$K$2:$K$1152) -> 0.011197917 | I22: =ROUND(AVERAGEIF('Uber Drives'!$N$2:$N$1152,F22,'Uber Drives'!$G$2:$G$1152),2) -> 5.7 | K22: {=UNIQUE({'Uber Drives'!M2:M1152,'Uber Drives'!N2:N1152})} -> Business | L22: Meal/Entertain | M22: =COUNTIFS('Uber Drives'!$M$2:$M$1152,K22,'Uber Drives'!$N$2:$N$1152,L22) -> 160 | N22: =AVERAGEIFS('Uber Drives'!$K$2:$K$1152,'Uber Drives'!$M$2:$M$1152,K22,'Uber Drives'!$N$2:$N$1152,L22) -> 0.011197917 | O22: =AVERAGEIFS('Uber Drives'!$G$2:$G$1152,'Uber Drives'!$M$2:$M$1152,K22,'Uber Drives'!$N$2:$N$1152,L22) -> 5.698125
A23: Personal | B23: =COUNTIF('Uber Drives'!$M$2:$M$1152,A23) -> 77 | C23: =AVERAGEIF('Uber Drives'!$M$2:$M$1152,$A$23,'Uber Drives'!$K$2:$K$1152) -> 0.014204545 | D23: =ROUND(AVERAGEIF('Uber Drives'!$M$2:$M$1152,$A$23,'Uber Drives'!$G$2:$G$1152),2) -> 9.32 | F23: NOT DEFINED | G23: =COUNTIF('Uber Drives'!$N$2:$N$1152,F23) -> 498 | H23: =AVERAGEIF('Uber Drives'!$N$2:$N$1152,F23,'Uber Drives'!$K$2:$K$1152) -> 0.016129797 | I23: =AVERAGEIF('Uber Drives'!$N$2:$N$1152,F23,'Uber Drives'!$G$2:$G$1152) -> 9.6757028 | K23: Business | L23: NOT DEFINED | M23: =COUNTIFS('Uber Drives'!$M$2:$M$1152,K23,'Uber Drives'!$N$2:$N$1152,L23) -> 427 | N23: =AVERAGEIFS('Uber Drives'!$K$2:$K$1152,'Uber Drives'!$M$2:$M$1152,K23,'Uber Drives'!$N$2:$N$1152,L23) -> 0.016692688 | O23: =AVERAGEIFS('Uber Drives'!$G$2:$G$1152,'Uber Drives'!$M$2:$M$1152,K23,'Uber Drives'!$N$2:$N$1152,L23) -> 10.103747
F24: Errand/Supplies | G24: =COUNTIF('Uber Drives'!$N$2:$N$1152,F24) -> 128 | H24: =AVERAGEIF('Uber Drives'!$N$2:$N$1152,F24,'Uber Drives'!$K$2:$K$1152) -> 0.0090115017 | I24: =AVERAGEIF('Uber Drives'!$N$2:$N$1152,F24,'Uber Drives'!$G$2:$G$1152) -> 3.96875 | K24: Business | L24: Errand/Supplies | M24: =COUNTIFS('Uber Drives'!$M$2:$M$1152,K24,'Uber Drives'!$N$2:$N$1152,L24) -> 128 | N24: =AVERAGEIFS('Uber Drives'!$K$2:$K$1152,'Uber Drives'!$M$2:$M$1152,K24,'Uber Drives'!$N$2:$N$1152,L24) -> 0.0090115017 | O24: =AVERAGEIFS('Uber Drives'!$G$2:$G$1152,'Uber Drives'!$M$2:$M$1152,K24,'Uber Drives'!$N$2:$N$1152,L24) -> 3.96875
F25: Meeting | G25: =COUNTIF('Uber Drives'!$N$2:$N$1152,F25) -> 187 | H25: =AVERAGEIF('Uber Drives'!$N$2:$N$1152,F25,'Uber Drives'!$K$2:$K$1152) -> 0.020651367 | I25: =AVERAGEIF('Uber Drives'!$N$2:$N$1152,F25,'Uber Drives'!$G$2:$G$1152) -> 15.247594 | K25: Business | L25: Meeting | M25: =COUNTIFS('Uber Drives'!$M$2:$M$1152,K25,'Uber Drives'!$N$2:$N$1152,L25) -> 187 | N25: =AVERAGEIFS('Uber Drives'!$K$2:$K$1152,'Uber Drives'!$M$2:$M$1152,K25,'Uber Drives'!$N$2:$N$1152,L25) -> 0.020651367 | O25: =AVERAGEIFS('Uber Drives'!$G$2:$G$1152,'Uber Drives'!$M$2:$M$1152,K25,'Uber Drives'!$N$2:$N$1152,L25) -> 15.247594
F26: Customer Visit | G26: =COUNTIF('Uber Drives'!$N$2:$N$1152,F26) -> 101 | H26: =AVERAGEIF('Uber Drives'!$N$2:$N$1152,F26,'Uber Drives'!$K$2:$K$1152) -> 0.023205446 | I26: =AVERAGEIF('Uber Drives'!$N$2:$N$1152,F26,'Uber Drives'!$G$2:$G$1152) -> 20.688119 | K26: Business | L26: Customer Visit | M26: =COUNTIFS('Uber Drives'!$M$2:$M$1152,K26,'Uber Drives'!$N$2:$N$1152,L26) -> 101 | N26: =AVERAGEIFS('Uber Drives'!$K$2:$K$1152,'Uber Drives'!$M$2:$M$1152,K26,'Uber Drives'!$N$2:$N$1152,L26) -> 0.023205446 | O26: =AVERAGEIFS('Uber Drives'!$G$2:$G$1152,'Uber Drives'!$M$2:$M$1152,K26,'Uber Drives'!$N$2:$N$1152,L26) -> 20.688119
F27: Temporary Site | G27: =COUNTIF('Uber Drives'!$N$2:$N$1152,F27) -> 50 | H27: =AVERAGEIF('Uber Drives'!$N$2:$N$1152,F27,'Uber Drives'!$K$2:$K$1152) -> 0.017958333 | I27: =AVERAGEIF('Uber Drives'!$N$2:$N$1152,F27,'Uber Drives'!$G$2:$G$1152) -> 10.474 | K27: Business | L27: Temporary Site | M27: =COUNTIFS('Uber Drives'!$M$2:$M$1152,K27,'Uber Drives'!$N$2:$N$1152,L27) -> 50 | N27: =AVERAGEIFS('Uber Drives'!$K$2:$K$1152,'Uber Drives'!$M$2:$M$1152,K27,'Uber Drives'!$N$2:$N$1152,L27) -> 0.017958333 | O27: =AVERAGEIFS('Uber Drives'!$G$2:$G$1152,'Uber Drives'!$M$2:$M$1152,K27,'Uber Drives'!$N$2:$N$1152,L27) -> 10.474
F28: Between Offices | G28: =COUNTIF('Uber Drives'!$N$2:$N$1152,F28) -> 18 | H28: =AVERAGEIF('Uber Drives'!$N$2:$N$1152,F28,'Uber Drives'!$K$2:$K$1152) -> 0.017708333 | I28: =AVERAGEIF('Uber Drives'!$N$2:$N$1152,F28,'Uber Drives'!$G$2:$G$1152) -> 10.944444 | K28: Business | L28: Between Offices | M28: =COUNTIFS('Uber Drives'!$M$2:$M$1152,K28,'Uber Drives'!$N$2:$N$1152,L28) -> 18 | N28: =AVERAGEIFS('Uber Drives'!$K$2:$K$1152,'Uber Drives'!$M$2:$M$1152,K28,'Uber Drives'!$N$2:$N$1152,L28) -> 0.017708333 | O28: =AVERAGEIFS('Uber Drives'!$G$2:$G$1152,'Uber Drives'!$M$2:$M$1152,K28,'Uber Drives'!$N$2:$N$1152,L28) -> 10.944444
F29: Charity ($) | G29: =COUNTIF('Uber Drives'!$N$2:$N$1152,F29) -> 1 | H29: =AVERAGEIF('Uber Drives'!$N$2:$N$1152,F29,'Uber Drives'!$K$2:$K$1152) -> 0.01875 | I29: =AVERAGEIF('Uber Drives'!$N$2:$N$1152,F29,'Uber Drives'!$G$2:$G$1152) -> 15.1 | K29: Personal | L29: NOT DEFINED | M29: =COUNTIFS('Uber Drives'!$M$2:$M$1152,K29,'Uber Drives'!$N$2:$N$1152,L29) -> 71 | N29: =AVERAGEIFS('Uber Drives'!$K$2:$K$1152,'Uber Drives'!$M$2:$M$1152,K29,'Uber Drives'!$N$2:$N$1152,L29) -> 0.012744523 | O29: =AVERAGEIFS('Uber Drives'!$G$2:$G$1152,'Uber Drives'!$M$2:$M$1152,K29,'Uber Drives'!$N$2:$N$1152,L29) -> 7.1014085
F30: Commute | G30: =COUNTIF('Uber Drives'!$N$2:$N$1152,F30) -> 1 | H30: =AVERAGEIF('Uber Drives'!$N$2:$N$1152,F30,'Uber Drives'!$K$2:$K$1152) -> 0.12847222 | I30: =AVERAGEIF('Uber Drives'!$N$2:$N$1152,F30,'Uber Drives'!$G$2:$G$1152) -> 180.2 | K30: Personal | L30: Charity ($) | M30: =COUNTIFS('Uber Drives'!$M$2:$M$1152,K30,'Uber Drives'!$N$2:$N$1152,L30) -> 1 | N30: =AVERAGEIFS('Uber Drives'!$K$2:$K$1152,'Uber Drives'!$M$2:$M$1152,K30,'Uber Drives'!$N$2:$N$1152,L30) -> 0.01875 | O30: =AVERAGEIFS('Uber Drives'!$G$2:$G$1152,'Uber Drives'!$M$2:$M$1152,K30,'Uber Drives'!$N$2:$N$1152,L30) -> 15.1
F31: Moving | G31: =COUNTIF('Uber Drives'!$N$2:$N$1152,F31) -> 4 | H31: =AVERAGEIF('Uber Drives'!$N$2:$N$1152,F31,'Uber Drives'!$K$2:$K$1152) -> 0.010416667 | I31: =AVERAGEIF('Uber Drives'!$N$2:$N$1152,F31,'Uber Drives'!$G$2:$G$1152) -> 4.55 | K31: Personal | L31: Commute | M31: =COUNTIFS('Uber Drives'!$M$2:$M$1152,K31,'Uber Drives'!$N$2:$N$1152,L31) -> 1 | N31: =AVERAGEIFS('Uber Drives'!$K$2:$K$1152,'Uber Drives'!$M$2:$M$1152,K31,'Uber Drives'!$N$2:$N$1152,L31) -> 0.12847222 | O31: =AVERAGEIFS('Uber Drives'!$G$2:$G$1152,'Uber Drives'!$M$2:$M$1152,K31,'Uber Drives'!$N$2:$N$1152,L31) -> 180.2
F32: Airport/Travel | G32: =COUNTIF('Uber Drives'!$N$2:$N$1152,F32) -> 3 | H32: =AVERAGEIF('Uber Drives'!$N$2:$N$1152,F32,'Uber Drives'!$K$2:$K$1152) -> 0.018055556 | I32: =AVERAGEIF('Uber Drives'!$N$2:$N$1152,F32,'Uber Drives'!$G$2:$G$1152) -> 5.5 | K32: Personal | L32: Moving | M32: =COUNTIFS('Uber Drives'!$M$2:$M$1152,K32,'Uber Drives'!$N$2:$N$1152,L32) -> 4 | N32: =AVERAGEIFS('Uber Drives'!$K$2:$K$1152,'Uber Drives'!$M$2:$M$1152,K32,'Uber Drives'!$N$2:$N$1152,L32) -> 0.010416667 | O32: =AVERAGEIFS('Uber Drives'!$G$2:$G$1152,'Uber Drives'!$M$2:$M$1152,K32,'Uber Drives'!$N$2:$N$1152,L32) -> 4.55
K33: Business | L33: Airport/Travel | M33: =COUNTIFS('Uber Drives'!$M$2:$M$1152,K33,'Uber Drives'!$N$2:$N$1152,L33) -> 3 | N33: =AVERAGEIFS('Uber Drives'!$K$2:$K$1152,'Uber Drives'!$M$2:$M$1152,K33,'Uber Drives'!$N$2:$N$1152,L33) -> 0.018055556 | O33: =AVERAGEIFS('Uber Drives'!$G$2:$G$1152,'Uber Drives'!$M$2:$M$1152,K33,'Uber Drives'!$N$2:$N$1152,L33) -> 5.5
A39: Висновок:
A40: Аналіз показав, що переважна більшість поїздок здійснюється в межах бізнес-категорії, зокрема з цілями Meeting, Meal/Entertain та Errand/Supplies. Такі поїздки мають вищі показники середньої тривалості та довжини, порівняно з персональними. Річна динаміка свідчить про зростання кількості поїздок у літні та зимові місяці, з піком у грудні. Активність за днями тижня є відносно стабільною, але підвищується у п’ятницю. За часом доби найбільша кількість поїздок припадає на денний та вечірній періоди, тоді як уночі активність суттєво знижується. Особисті (Personal) поїздки становлять незначну частку та не демонструють чіткої сезонності. Отже, можна зробити висновок, що ділові поїздки формують основну частину активності користувачів сервісу Uber у 2016 році.

Sheet Result Pivot Table
A1: 1. Аналіз поїздок за категоріями та ціллю - кількість поїздок, середня тривалість поїздок, середня довжина поїздок (милі)
A2: b. Підрахунок за допомогою зведеної таблиці
A3: CATEGORY | B3: PURPOSE | C3: Кількість поїздок | D3: Середня тривалість поїздок | E3: Середня довжина поїздок
A4: Business | B4: Airport/Travel | C4: 3 | D4: 0.018055556 | E4: 5.5
B5: Between Offices | C5: 18 | D5: 0.017708333 | E5: 10.944444
B6: Customer Visit | C6: 101 | D6: 0.023205446 | E6: 20.688119
B7: Errand/Supplies | C7: 128 | D7: 0.0090115017 | E7: 3.96875
B8: Meal/Entertain | C8: 160 | D8: 0.011197917 | E8: 5.698125
B9: Meeting | C9: 187 | D9: 0.020651367 | E9: 15.247594
B10: NOT DEFINED | C10: 427 | D10: 0.016692688 | E10: 10.103747
B11: Temporary Site | C11: 50 | D11: 0.017958333 | E11: 10.474
A12: Personal | B12: Charity ($) | C12: 1 | D12: 0.01875 | E12: 15.1
B13: Commute | C13: 1 | D13: 0.12847222 | E13: 180.2
B14: Moving | C14: 4 | D14: 0.010416667 | E14: 4.55
B15: NOT DEFINED | C15: 71 | D15: 0.012744523 | E15: 7.1014085
A17: 2. Річна динаміка кількості поїздок, середньої тривалості та довжини поїздок по місяцям
A33: 2. Річна динаміка кількості поїздок, середньої тривалості та довжини поїздок по дням тижня
A48: a. Рчна динаміка кількості поїздок по місяцям, в залежності від категорії поїздки
A69: 3. Залежність кількості поїздок по категоріям від часу доби (категоризоване значення часу)
